<?xml version="1.0" encoding="UTF-8"?>
<robot name="golf">

  <gazebo>
    <plugin filename="libgazebo_ros_p3d.so" name="p3d">
      <alwaysOn>true</alwaysOn>
      <updateRate>50.0</updateRate>
      <bodyName>chassis</bodyName>
      <topicName>base_pose_ground_truth</topicName>
      <gaussianNoise>0.0</gaussianNoise>
      <frameName>world</frameName>
      <xyzOffsets>0 0 0</xyzOffsets>
      <rpyOffsets>0 0 0</rpyOffsets>
    </plugin>
  </gazebo>

  <gazebo>
    <plugin name="plugin" filename="libcartplugin.so">
      <chassis>chassis</chassis>
      <front_left_wheel>front_left_wheel_joint</front_left_wheel>
      <front_right_wheel>front_right_wheel_joint</front_right_wheel>
      <front_left_wheel_steering>front_left_steer_joint</front_left_wheel_steering>
      <front_right_wheel_steering>front_right_steer_joint</front_right_wheel_steering>
      <back_left_wheel>rear_left_wheel_joint</back_left_wheel>
      <back_right_wheel>rear_right_wheel_joint</back_right_wheel>
      <steering_wheel>steering_joint</steering_wheel>
      <chassis_aero_force_gain>0.63045</chassis_aero_force_gain>
      <front_torque>0.0</front_torque>
      <back_torque>400.4004393000001</back_torque>
      <front_brake_torque>331.28052716</front_brake_torque>
      <back_brake_torque>187.5203514400001</back_brake_torque>
      <max_speed>37.998337013956565</max_speed>
      <min_gas_flow>8.981854013171626e-05</min_gas_flow>
      <gas_efficiency>0.371</gas_efficiency>
      <battery_charge_watt_hours>291</battery_charge_watt_hours>
      <battery_discharge_watt_hours>214</battery_discharge_watt_hours>
      <max_steer>0.6458</max_steer>
      <flwheel_steering_p_gain>1e4</flwheel_steering_p_gain>
      <frwheel_steering_p_gain>1e4</frwheel_steering_p_gain>
      <flwheel_steering_i_gain>0</flwheel_steering_i_gain>
      <frwheel_steering_i_gain>0</frwheel_steering_i_gain>
      <flwheel_steering_d_gain>3e2</flwheel_steering_d_gain>
      <frwheel_steering_d_gain>3e2</frwheel_steering_d_gain>
    </plugin>
  </gazebo>

  <gazebo>
    <plugin filename="libgazebo_ros_joint_state_publisher.so" name="joint_state_publisher">
      <!-- <robotNamespace>/prius</robotNamespace> -->
      <jointName>rear_right_wheel_joint, rear_left_wheel_joint, front_right_wheel_joint, front_left_wheel_joint, front_right_steer_joint, front_left_steer_joint,steering_joint</jointName>
      <updateRate>100.0</updateRate>
      <alwaysOn>true</alwaysOn>
    </plugin>
  </gazebo>

  <gazebo reference="front_left_wheel">
    <mu1>0.9</mu1>
    <mu2>0.9</mu2>
    <minDepth>0.005</minDepth>
    <kp>1e8</kp>
  </gazebo>

  <gazebo reference="front_right_wheel">
    <mu1>0.9</mu1>
    <mu2>0.9</mu2>
    <minDepth>0.005</minDepth>
    <kp>1e8</kp>
  </gazebo>

  <gazebo reference="rear_left_wheel">
    <mu1>0.9</mu1>
    <mu2>0.9</mu2>
    <minDepth>0.005</minDepth>
    <kp>1e8</kp>
  </gazebo>

  <gazebo reference="rear_right_wheel">
    <mu1>0.9</mu1>
    <mu2>0.9</mu2>
    <minDepth>0.005</minDepth>
    <kp>1e8</kp>
  </gazebo>
<!--  
  <link name="base_link">

  </link>

  <joint name="fixed" type="fixed">
    <parent link="base_link"/>
    <child link="chassis"/>
  </joint> -->
  
  <!-- Front Chassis -->
  <link name="chassis">
    <inertial>
      <origin xyz="0 0 0" rpy="0 0 0"/>
      <mass value="250"/>
      <inertia ixx="258.113354740" ixy="0.0" ixz="0.0" iyy="59.130846112" iyz="0.0" izz="268.195008628"/>
    </inertial>
    <visual>
      <origin xyz="0 0 0.0" rpy="0 0 0"/>
      <geometry>
        <mesh filename="package://cart_sim/models/golf/meshes/chassis.dae" scale="1 1 1"/>
      </geometry>
    </visual>
  

    <collision name="sub">
      <origin xyz="0.215994 0 0.246225" rpy="0 0 0"/>
      <geometry>
        <box size="1 1.3 0.2 "/>
      </geometry>
    </collision>
    <collision name="subf">
      <origin xyz="1.17696 0 0.242774" rpy="0 0 0"/>
      <geometry>
        <box size="0.6  0.55 0.1"/>
      </geometry>
    </collision>
        <collision name="subb">
      <origin xyz="-0.600259 0 0.242774" rpy="0 0 0"/>
      <geometry>
        <box size="0.6  0.55 0.1"/>
      </geometry>
    </collision>
       <collision name="front_chas">
      <origin xyz="0.862069 0 0.697802" rpy="0 0 0"/>
      <geometry>
        <box size="0.7 1.2 0.3"/>
      </geometry>
    </collision>
    <collision name="bumper">
      <origin xyz="1.18666 -0.00473 0.394144" rpy="0 0 0"/>
      <geometry>
        <box size="0.2 0.35 0.2"/>
      </geometry>
    </collision>
      <collision name="back_chas">
      <origin xyz="-0.558996 0 0.631874" rpy="0 0 0"/>
      <geometry>
        <box size="1.2 1.3 0.15"/>
      </geometry>
    </collision>
          <collision name="back_bumper">
      <origin xyz="-1.06928 0 0.409309" rpy="0 0 0"/>
      <geometry>
        <box size="0.25 1.3 0.3"/>
      </geometry>
    </collision>
           <collision name="seats">
      <origin xyz="-0.453409 0 0.965925" rpy="0 0 0"/>
      <geometry>
        <box size="0.13 1 0.5"/>
      </geometry>
    </collision>
         <collision name="roof">
      <origin xyz="-0.301688 0 1.81143" rpy="0 0 0"/>
      <geometry>
        <box size="2.2 1.3 0.1"/>
      </geometry>
    </collision>
       <collision name="roof">
      <origin xyz="-0.301688 0 1.81143" rpy="0 0 0"/>
      <geometry>
        <box size="2.2 1.3 0.1"/>
      </geometry>
    </collision>
    <collision name="steering">
      <origin xyz="0.472249 0.251507 0.94451" rpy="0  -0.6981317008 0"/>
      <geometry>
        <cylinder length="0.4" radius="0.035"/>
      </geometry>
    </collision>
  </link>
  <!-- Front Wheels -->
  <link name="front_left_wheel">
    <inertial>
      <origin xyz="0 0 0" rpy="0 0 0"/>
      <mass value="11"/>
      <inertia ixx="0.18631238" ixy="0.0" ixz="0.0" iyy="0.06552910" iyz="0.0" izz="0.06552910"/>
    </inertial>
    <visual>
      <origin xyz="0 0 0" rpy="0 0 0"/>
      <geometry>
        <mesh filename="package://cart_sim/models/golf/meshes/whl.dae" scale="1 1 1"/>
      </geometry>
    </visual>
    <collision name="front_left_wheel_collision">
      <origin xyz="0 0 0" rpy="1.5708 0 0"/>
      <geometry>
        <cylinder length="0.202" radius="0.2575"/>
      </geometry>
    </collision>
  </link>

  <link name="front_right_wheel">
    <pose xyz="0 0 0" rpy="0 0 0"/>
    <inertial>
      <origin xyz="0 0 0" rpy="0 0 0"/>
      <mass value="11"/>
      <inertia ixx="0.18631238" ixy="0.0" ixz="0.0" iyy="0.06552910" iyz="0.0" izz="0.06552910"/>
    </inertial>
    <visual>
      <origin xyz="0 0 0" rpy="0 0 0"/>
      <geometry>
        <mesh filename="package://cart_sim/models/golf/meshes/whl.dae" scale="1 1 1"/>
      </geometry>
    </visual>
    <collision name="front_right_wheel_collision">
      <origin xyz="0 0 0" rpy="1.5708 0 0"/>
      <geometry>
        <cylinder length="0.202" radius="0.2575"/>
      </geometry>
    </collision>
  </link>

  <link name="fl_axle">
    <inertial>
      <mass value="1"/>
      <origin xyz="0 0 0"/>
      <inertia ixx="0.004" ixy="0.0" ixz="0.0" iyy="0.004" iyz="0.0" izz="0.004"/>
    </inertial>
    <visual>
      <origin xyz="0 0 0" rpy="0 0 0"/>
      <geometry>
        <mesh filename="package://cart_sim/models/golf/meshes/susp.dae" scale="1 1 1"/>
      </geometry>
    </visual>
  </link>

  <link name="fr_axle">
    <inertial>
      <mass value="1"/>
      <origin xyz="0 0 0"/>
      <inertia ixx="0.004" ixy="0.0" ixz="0.0" iyy="0.004" iyz="0.0" izz="0.004"/>
    </inertial>
    <visual>
      <origin xyz="0 0 0" rpy="0 0 3.14"/>
      <geometry>
        <mesh filename="package://cart_sim/models/golf/meshes/susp.dae" scale="1 1 1"/>
      </geometry>
    </visual>
  </link>

  <link name="rear_left_wheel">
    <pose xyz="0 0 0" rpy="0 0 0"/>
    <inertial>
      <origin xyz="0 0 0" rpy="0 0 0"/>
      <mass value="11"/>
      <inertia ixx="0.18631238" ixy="0.0" ixz="0.0" iyy="0.06552910" iyz="0.0" izz="0.06552910"/>
    </inertial>
    <visual>
      <origin xyz="0 0 0" rpy="0 0 0"/>
      <geometry>
        <mesh filename="package://cart_sim/models/golf/meshes/whl.dae" scale="1 1 1"/>
      </geometry>
    </visual>
    <collision name="collision">
      <origin xyz="0 0 0" rpy="1.5708 0 0"/>
      <geometry>
        <cylinder length="0.202" radius="0.2575"/>
      </geometry>
    </collision>
  </link>

  <link name="rear_right_wheel">
    <pose xyz="0 0 0" rpy="0 0 0"/>
    <inertial>
      <origin xyz="0 0 0" rpy="0 0 0"/>
      <mass value="11"/>
      <inertia ixx="0.18631238" ixy="0.0" ixz="0.0" iyy="0.06552910" iyz="0.0" izz="0.06552910"/>
    </inertial>
    <visual>
      <origin xyz="0 0 0" rpy="0 0 0"/>
      <geometry>
        <mesh filename="package://cart_sim/models/golf/meshes/whl.dae" scale="1 1 1"/>
      </geometry>
    </visual>
    <collision name="collision">
      <origin xyz="0 0 0" rpy="1.5708 0 0"/>
      <geometry>
        <cylinder length="0.202" radius="0.2575"/>
      </geometry>
    </collision>
  </link>
  
  <link name="steering_wheel">
    <inertial>
      <mass value="1.0"/>
      <inertia ixx="0.14583300" ixy="0.0" ixz="0.0" iyy="0.14583300" iyz="0.0" izz="0.125"/>
    </inertial>
    <visual>
      <origin xyz="0 0 0" rpy="0 0 0"/>
      <geometry>
        <mesh filename="package://cart_sim/models/golf/meshes/steer.dae" scale="1 1 1"/>
      </geometry>
    </visual>
  </link>
  
  <joint name="steering_joint" type="continuous">
    <origin xyz="0.287517 0.252014 1.16092" rpy="0 -0.6981317008 0"/>
    <parent link="chassis"/>
    <child link="steering_wheel"/>
    <axis xyz="0 0 1"/>
    <limit lower="-3.14" upper="3.14" effort="10000000" velocity="1000000"/>
  </joint>

  
<joint name="front_left_steer_joint" type="revolute">
  <parent link="chassis"/>
  <child link="fl_axle"/>
  <origin xyz="0.997567 0.464828 0.284127" rpy="0 0 0"/>
  <axis xyz="0 0 1"/>
  <limit lower="-0.6109" upper=" 0.6109" effort="10000000" velocity="1000000"/>
</joint>

<joint name="front_right_steer_joint" type="revolute">
  <parent link="chassis"/>
  <child link="fr_axle"/>
  <origin xyz="0.997567 -0.464828 0.284127" rpy="0 0 0"/>
  <axis xyz="0 0 1"/>
  <limit lower="-0.6109" upper=" 0.6109" effort="10000000" velocity="1000000"/>
</joint>

<joint type="continuous" name="front_left_wheel_joint">
  <parent link="fl_axle"/>
  <child link="front_left_wheel"/>
  <origin xyz="0.0001 0.045269 -0.009017" rpy=" 0 0 0"/>
  <origin xyz="0 0 0" rpy="0 0 0"/>
  <axis xyz="0 1 0"/>
</joint>

<joint type="continuous" name="front_right_wheel_joint">
  <parent link="fr_axle"/>
  <child link="front_right_wheel"/>
  <origin xyz="0.0001 -0.045269 -0.009017" rpy=" 0 0 0"/>
  <origin xyz="0 0 0" rpy="0 0 0"/>
  <axis xyz="0 1 0"/>
</joint>

<joint type="continuous" name="rear_left_wheel_joint">
  <origin xyz="-0.601769 0.53556 0.272108" rpy="0 0 0"/>
  <parent link="chassis"/>
  <child link="rear_left_wheel"/>
  <axis xyz="0 1 0"/>
</joint>

<joint type="continuous" name="rear_right_wheel_joint">
  <origin xyz="-0.601769 -0.53556 0.272108 " rpy="0 0 0"/>
  <parent link="chassis"/>
  <child link="rear_right_wheel"/>
  <axis xyz="0 1 0"/>
</joint>
  
<link name="lidar_link">
  
    <visual>
      <geometry>
        <box size="0.1 0.1 0.1"/>
      </geometry>
    </visual>
    
    <inertial>
      <origin xyz="0.77 0 1.81" rpy="0 -0.2 -3.141591"/>
      <mass value="1"/>
      <inertia ixx="3.0" ixy="0.0" ixz="0.0" iyy="3.0" iyz="0.0" izz="3.0"/>
    </inertial>
    
</link>
  
<link name="velodyne_base_link">

  <inertial>
    <mass value="0.83"/>
    <origin xyz="0.77 0 1.81"/>
    <inertia ixx="0.000908059425" ixy="0" ixz="0" iyy="0.000908059425" iyz="0" izz="0.0011049624"/>
  </inertial>
  
  <visual>
    <geometry>
      <mesh filename="package://velodyne_description/meshes/VLP16_base_1.dae"/>
    </geometry>
  </visual>
  
  <visual>
    <geometry>
      <mesh filename="package://velodyne_description/meshes/VLP16_base_2.dae"/>
    </geometry>
  </visual>
  
  <collision>
    <origin rpy="0 0 0" xyz="0 0 0.03585"/>
    <geometry>
      <cylinder length="0.0717" radius="0.0516"/>
    </geometry>
  </collision>
  
</link>

<joint name="lidar_to_body" type="fixed">
  <parent link="chassis"/>
  <child link="lidar_link"/>
  <origin rpy="0 0 0" xyz="0.9 0 0.8"/>
</joint>

<joint name="velodyne_base_mount_joint" type="fixed">
  <origin rpy="0 0 0" xyz="0 0 0.05"/>
  <parent link="lidar_link"/>
  <child link="velodyne_base_link"/>
</joint>

<joint name="velodyne_base_scan_joint" type="fixed">
  <origin rpy="0 0 0" xyz="0 0 0.0377"/>
  <parent link="velodyne_base_link"/>
  <child link="velodyne"/>
</joint>
  
  <link name="velodyne">
  
    <inertial>
      <mass value="0.01"/>
      <origin xyz="0 0 0"/>
      <inertia ixx="1e-7" ixy="0" ixz="0" iyy="1e-7" iyz="0" izz="1e-7"/>
    </inertial>
    
    <visual>
      <origin xyz="0 0 -0.0377"/>
      <geometry>
        <mesh filename="package://velodyne_description/meshes/VLP16_scan.dae"/>
      </geometry>
    </visual>
    
  </link>

 
  <gazebo reference="velodyne_base_mount_joint">
    <disableFixedJointLumping>true</disableFixedJointLumping>
    <preserveFixedJoint>true</preserveFixedJoint>
  </gazebo>
  
  <gazebo reference="velodyne_base_scan_joint">
    <disableFixedJointLumping>true</disableFixedJointLumping>
    <preserveFixedJoint>true</preserveFixedJoint>
  </gazebo>
  
  <gazebo reference="velodyne">
  
    <sensor name="velodyne-VLP16" type="gpu_ray">
      <pose>0 0 0 0 0 0</pose>
      <visualize>0</visualize>
      <update_rate>10</update_rate>
      
      <ray>
      
        <scan>
        
          <horizontal>
            <samples>440</samples>
            <resolution>1</resolution>
            <min_angle>-3.14159265359</min_angle>
            <max_angle>3.14159265359</max_angle>
          </horizontal>
          
          <vertical>
            <samples>16</samples>
            <resolution>1</resolution>
            <min_angle>-0.261799387799</min_angle>
            <max_angle> 0.261799387799</max_angle>
          </vertical>
          
        </scan>
        
        <range>
          <min>0.3</min>
          <max>131.0</max>
          <resolution>0.001</resolution>
        </range>
        
        <noise>
          <type>gaussian</type>
          <mean>0.0</mean>
          <stddev>0.0</stddev>
        </noise>
        
      </ray>
      
      <plugin filename="libgazebo_ros_velodyne_gpu_laser.so" name="gazebo_ros_laser_controller">
        <topicName>/cart/center_laser/scan</topicName>
        <frameName>velodyne</frameName>
        <organize_cloud>False</organize_cloud>
        <min_range>0.9</min_range>
        <max_range>100.0</max_range>
        <gaussianNoise>0.008</gaussianNoise>
      </plugin>
      
    </sensor>
    
  </gazebo>
  
  <link name="front_camera_link">
    <inertial>
      <mass value="1"/>
      <inertia ixx="0.001" ixy="0.0" ixz="0.0" iyy="0.001" iyz="0.0" izz="0.001"/>
    </inertial>
  </link>
  <joint name="front_camera_joint" type="fixed">
    <parent link="chassis"/>
    <child link="front_camera_link"/>
    <origin xyz="0.9 0 1" rpy="0 0.05 0"/>
  </joint>
  <link name="front_camera_link_optical">
    <inertial>
      <mass value="1"/>
      <inertia ixx="0.001" ixy="0.0" ixz="0.0" iyy="0.001" iyz="0.0" izz="0.001"/>
    </inertial>
  </link>
  <joint name="front_camera_optical_joint" type="fixed">
    <origin xyz="0 0 0" rpy="0 0 0"/>
    <parent link="front_camera_link"/>
    <child link="front_camera_link_optical"/>
  </joint>
  <gazebo reference="front_camera_link">
    <sensor type="camera" name="front_camera_sensor">
      <update_rate>30.0</update_rate>
      <camera name="front_camera">
        <horizontal_fov>1.507</horizontal_fov>
        <image>
          <width>1280</width>
          <height>960</height>
          <format>R8G8B8</format>
        </image>
        <clip>
          <near>0.02</near>
          <far>300</far>
        </clip>
        <noise>
          <type>gaussian</type>
          <mean>0.0</mean>
          <stddev>0.007</stddev>
        </noise>
      </camera>
      <plugin name="front_camera_controller" filename="libgazebo_ros_camera.so">
        <alwaysOn>false</alwaysOn>
        <updateRate>0.0</updateRate>
        <cameraName>/cart/front_camera</cameraName>
        <imageTopicName>image_raw</imageTopicName>
        <cameraInfoTopicName>/cart/front_camera/camera_info</cameraInfoTopicName>
        <frameName>front_camera_link_optical</frameName>
        <hackBaseline>0.07</hackBaseline>
        <distortionK1>0.0</distortionK1>
        <distortionK2>0.0</distortionK2>
        <distortionK3>0.0</distortionK3>
        <distortionT1>0.0</distortionT1>
        <distortionT2>0.0</distortionT2>
      </plugin>
    </sensor>
  </gazebo>
  

  <gazebo reference="lidar_link">
    <material>Gazebo/Black</material>
  </gazebo>

<gazebo reference="lidar_to_body">
    <disableFixedJointLumping>true</disableFixedJointLumping>
    <preserveFixedJoint>true</preserveFixedJoint>
  </gazebo>

<link name="depth_world">
  <inertial>
    <mass value="1"/>
    <inertia ixx="0.001" ixy="0.0" ixz="0.0" iyy="0.001" iyz="0.0" izz="0.001"/>
  </inertial>
</link>

<joint name="world_joint" type="fixed">
  <origin xyz="0 0 0" rpy="0 0 0"/>
  <parent link="chassis"/>
  <child link="depth_world"/>
</joint>
</robot>
